Workbook

Sheet testset_100
A1: คำเตือน: ลิงก์กลุ่ม phish_fresh เป็นเว็บหลอกที่ยังทำงานอยู่จริง — ห้ามเปิด ใช้สำหรับทดสอบระบบเท่านั้น
A2: ลำดับ | B2: ลิงก์ (url) | C2: ความจริง (label) | D2: กลุ่ม (stratum) | E2: ระบบเรา: ผล | F2: ระบบเรา: คะแนน | G2: ระบบเรา: สัญญาณที่เจอ | H2: ระบบเรา: ถูก/ผิด | I2: คู่แข่ง: % คิดว่าหลอก | J2: คู่แข่ง: ผล | K2: คู่แข่ง: ถูก/ผิด | L2: ใครถูก
A3: 1 | B3: https://www.google.com | C3: safe | D3: global_popular | E3: green | F3: 0 | G3: verified_brand | H3: ถูก | I3: 0.30872082 | J3: not_red | K3: ถูก | L3: ถูกทั้งคู่
A4: 2 | B4: https://www.youtube.com | C4: safe | D4: global_popular | E4: green | F4: 0 | G4: verified_brand | H4: ถูก | I4: 0.28840679 | J4: not_red | K4: ถูก | L4: ถูกทั้งคู่
A5: 3 | B5: https://www.facebook.com | C5: safe | D5: global_popular | E5: green | F5: 0 | G5: verified_brand | H5: ถูก | I5: 0.29641051 | J5: not_red | K5: ถูก | L5: ถูกทั้งคู่
A6: 4 | B6: https://github.com | C6: safe | D6: global_popular | E6: green | F6: 0 | G6: verified_brand | H6: ถูก | I6: 0.63923601 | J6: not_red | K6: ถูก | L6: ถูกทั้งคู่
A7: 5 | B7: https://www.amazon.com | C7: safe | D7: global_popular | E7: green | F7: 0 | G7: verified_brand | H7: ถูก | I7: 0.30961446 | J7: not_red | K7: ถูก | L7: ถูกทั้งคู่
A8: 6 | B8: https://www.netflix.com | C8: safe | D8: global_popular | E8: green | F8: 0 | G8: verified_brand | H8: ถูก | I8: 0.36545462 | J8: not_red | K8: ถูก | L8: ถูกทั้งคู่
A9: 7 | B9: https://www.linkedin.com | C9: safe | D9: global_popular | E9: green | F9: 0 | G9: verified_brand | H9: ถูก | I9: 0.33039066 | J9: not_red | K9: ถูก | L9: ถูกทั้งคู่
A10: 8 | B10: https://www.instagram.com | C10: safe | D10: global_popular | E10: green | F10: 0 | G10: verified_brand | H10: ถูก | I10: 0.33410735 | J10: not_red | K10: ถูก | L10: ถูกทั้งคู่
A11: 9 | B11: https://www.microsoft.com | C11: safe | D11: global_popular | E11: green | F11: 0 | G11: verified_brand | H11: ถูก | I11: 0.32929628 | J11: not_red | K11: ถูก | L11: ถูกทั้งคู่
A12: 10 | B12: https://www.apple.com | C12: safe | D12: global_popular | E12: green | F12: 0 | G12: verified_brand | H12: ถูก | I12: 0.34644136 | J12: not_red | K12: ถูก | L12: ถูกทั้งคู่
A13: 11 | B13: https://www.wikipedia.org | C13: safe | D13: global_outside | E13: green | F13: 0 | G13: popular_domain | H13: ถูก | I13: 0.27585505 | J13: not_red | K13: ถูก | L13: ถูกทั้งคู่
A14: 12 | B14: https://stackoverflow.com | C14: safe | D14: global_outside | E14: green | F14: 0 | G14: popular_domain | H14: ถูก | I14: 0.58443702 | J14: not_red | K14: ถูก | L14: ถูกทั้งคู่
... A102: 100 | B102: https://s.teams-rf.com/p/fjbd-cbch/zoogzziw/ | C102: dangerous | D102: phish_fresh | E102: yellow | F102: 0 | G102: - | H102: ผิด | I102: 0.13173125 | J102: not_red | K102: ผิด | L102: ผิดทั้งคู่

Sheet สรุปผล
A1: สรุปผลการทดสอบ 100 ลิงก์ — เทียบระบบของโครงงานกับคู่แข่ง
A2: ระบบเรา: ตรวจแค่ชั้น 1-2 (run_deep=False) บัญชีดำ สกมช. โหลดไม่ได้ | คู่แข่ง: Logistic Regression ฝึกจาก PhiUSIIL (UCI) เห็นแค่ชื่อโดเมน
A3: ทั้งสองระบบถูกบังคับให้ "ห้ามเตือนเว็บจริงผิดแม้แต่เส้นเดียว" เท่ากัน จึงเทียบกันได้อย่างยุติธรรม
A5: 1) ตารางความสับสน — ระบบของเรา
B6: ตอบ แดง | C6: ตอบ ไม่แดง | D6: รวม
A7: ความจริง: อันตราย | B7: =COUNTIFS(testset_100!$C$3:$C$102,"dangerous",testset_100!$E$3:$E$102,"red") | C7: =COUNTIFS(testset_100!$C$3:$C$102,"dangerous")-B7 | D7: =B7+C7
A8: ความจริง: ปลอดภัย | B8: =COUNTIFS(testset_100!$C$3:$C$102,"safe",testset_100!$E$3:$E$102,"red") | C8: =COUNTIFS(testset_100!$C$3:$C$102,"safe")-B8 | D8: =B8+C8
A10: 2) ตารางความสับสน — คู่แข่ง (Logistic Regression)
B11: ตอบ แดง | C11: ตอบ ไม่แดง | D11: รวม
A12: ความจริง: อันตราย | B12: =COUNTIFS(testset_100!$C$3:$C$102,"dangerous",testset_100!$J$3:$J$102,"red") | C12: =COUNTIFS(testset_100!$C$3:$C$102,"dangerous")-B12 | D12: =B12+C12
A13: ความจริง: ปลอดภัย | B13: =COUNTIFS(testset_100!$C$3:$C$102,"safe",testset_100!$J$3:$J$102,"red") | C13: =COUNTIFS(testset_100!$C$3:$C$102,"safe")-B13 | D13: =B13+C13
A15: 3) เทียบตัวชี้วัด
A16: ตัวชี้วัด | B16: ระบบเรา | C16: คู่แข่ง | D16: ความหมาย
A17: จับลิงก์หลอกได้ (Recall) | B17: =B7/D7 | C17: =B12/D12 | D17: ลิงก์อันตรายทั้งหมด เตือนแดงได้กี่ %
A18: เตือนผิด (False Positive rate) | B18: =B8/D8 | C18: =B13/D13 | D18: เว็บจริงโดนเตือนแดงผิดกี่ % (ยิ่งต่ำยิ่งดี)
A19: ความแม่นของคำเตือน (Precision) | B19: =IF((B7+B8)=0,0,B7/(B7+B8)) | C19: =IF((B12+B13)=0,0,B12/(B12+B13)) | D19: เวลาขึ้นแดง ถูกจริงกี่ %
A20: ความถูกต้องรวม (Accuracy) | B20: =(B7+C8)/(D7+D8) | C20: =(B12+C13)/(D12+D13) | D20: ตอบถูกกี่ % จากทั้งหมด
A22: 4) ใครตอบถูก แยกเป็นกลุ่ม
A23: กรณี | B23: จำนวนลิงก์ | C23: ความหมาย
A24: ถูกทั้งคู่ | B24: =COUNTIF(testset_100!$L$3:$L$102,A24) | C24: ทั้งสองระบบตอบตรงกับความจริง
A25: เฉพาะระบบเรา | B25: =COUNTIF(testset_100!$L$3:$L$102,A25) | C25: ระบบเราตอบถูก คู่แข่งตอบผิด
A26: เฉพาะคู่แข่ง | B26: =COUNTIF(testset_100!$L$3:$L$102,A26) | C26: คู่แข่งตอบถูก ระบบเราตอบผิด
A27: ผิดทั้งคู่ | B27: =COUNTIF(testset_100!$L$3:$L$102,A27) | C27: ทั้งสองระบบตอบผิด
A29: 5) นับสีเหลืองเป็นการเตือนด้วย (เฉพาะระบบเรา)
A30: ระบบของเรามีสถานะกลางคือสีเหลือง ซึ่งเตือนผู้ใช้อยู่แต่ไม่ฟันธง ตัวเลขข้างบนนับเฉพาะสีแดง เพราะคู่แข่งมีแค่เตือนกับไม่เตือน
A31: รายการ | B31: จำนวน | C31: คิดเป็น %
A32: เว็บหลอกที่ได้เหลืองหรือแดง | B32: =COUNTIFS(testset_100!$C$3:$C$102,"dangerous")-COUNTIFS(testset_100!$C$3:$C$102,"dangerous",testset_100!$E$3:$E$102,"green") | C32: =B32/D7
A33: เว็บจริงที่ได้เหลืองหรือแดง | B33: =COUNTIFS(testset_100!$C$3:$C$102,"safe")-COUNTIFS(testset_100!$C$3:$C$102,"safe",testset_100!$E$3:$E$102,"green") | C33: =B33/D8
A34: เว็บหลอกที่ระบบเราตอบเขียว | B34: =COUNTIFS(testset_100!$C$3:$C$102,"dangerous",testset_100!$E$3:$E$102,"green") | C34: =B34/D7
A36: 6) ถ้าตั้งเกณฑ์ของระบบเราให้เข้มเท่าคู่แข่ง
A37: ตอนนี้ระบบเราใช้ RED_SCORE=6 ซึ่งเข้มกว่าที่จำเป็น ถ้าลดเกณฑ์ลงมาให้ยอม เตือนผิด 0% เท่ากับคู่แข่งพอดี (คือแดงเมื่อคะแนน >= 1) จะได้ผลตามนี้
A38: รายการ | B38: จำนวน | C38: คิดเป็น %
A39: เว็บหลอกที่คะแนน >= 1 | B39: =COUNTIFS(testset_100!$C$3:$C$102,"dangerous",testset_100!$F$3:$F$102,">=1") | C39: =B39/D7
A40: เว็บจริงที่คะแนน >= 1 | B40: =COUNTIFS(testset_100!$C$3:$C$102,"safe",testset_100!$F$3:$F$102,">=1") | C40: =B40/D8
A41: ตัวเลขนี้คือค่าที่ใช้ในหน้าเว็บสาธิต ส่วนตัวเลขในข้อ 1 และ 3 คือผลของเกณฑ์ที่ระบบใช้งานจริงตอนนี้
A43: หมายเหตุ
A44: แถวที่เลขลำดับมีพื้นสีเหลือง = แถวที่ระบบของเราตอบผิด
A45: ตอบถูก หมายถึง ลิงก์อันตราย -> แดง / เว็บจริง -> ไม่แดง
A46: คู่แข่งใช้เกณฑ์ตัดที่ 0.9724 ซึ่งเป็นค่าต่ำสุดที่ยังไม่เตือนเว็บจริงผิดเลย
A47: คู่แข่งเห็นแค่ชื่อโดเมน ไม่เห็น path และไม่มีรายการแบรนด์ จึงเทียบได้กับชั้น 1-2 เท่านั้น
...
